/cm/local/apps/torque/4.2.4.1/spool/mom_priv/jobs/8562813.master.cm.cluster.SC: line 4: print_passed_variables: command not found
/cm/local/apps/torque/4.2.4.1/spool/mom_priv/jobs/8562813.master.cm.cluster.SC: line 5: ((: == 1 : syntax error: operand expected (error token is "== 1 ")
rm: cannot remove `dump.rdb': No such file or directory
+ job_id=8562813.master.cm.cluster
++ cut -d. -f1
+ job_number=8562813
+ echo 'Job id is 8562813'
+ echo 8562813
+ cd /panfs/panasas01/phys/bf16951/QMD/ParallelDevelopment
+ mkdir -p /panfs/panasas01/phys/bf16951/QMD/ParallelDevelopment/logs
+ mkdir -p /newhome/bf16951/QMD/ParallelDevelopment/logs
+ REDIS_URL=redis://node44-013:6323
+ QMD_LOG_DIR=/panfs/panasas01/phys/bf16951/QMD/ParallelDevelopment/Results/Jul_05/17_09/logs
+ OUTPUT_ERROR_DIR=/panfs/panasas01/phys/bf16951/QMD/ParallelDevelopment/Results/Jul_05/17_09/output_and_error_logs
+ mkdir -p /panfs/panasas01/phys/bf16951/QMD/ParallelDevelopment/Results/Jul_05/17_09/logs
+ QMD_JOB=exp-paper__simulated-data__plus-probes_23
+ echo 'PBS job name is exp-paper__simulated-data__plus-probes_23'
+ QMD_LOG=/panfs/panasas01/phys/bf16951/QMD/ParallelDevelopment/Results/Jul_05/17_09/logs/exp-paper__simulated-data__plus-probes_23.qmd.8562813.log
+ cat /cm/local/apps/torque/4.2.4.1/spool/aux//8562813.master.cm.cluster
++ cat /cm/local/apps/torque/4.2.4.1/spool/aux//8562813.master.cm.cluster
+ export 'nodes=node44-013
node44-013
node44-013
node44-013
node44-013'
+ nodes='node44-013
node44-013
node44-013
node44-013
node44-013'
++ cat /cm/local/apps/torque/4.2.4.1/spool/aux//8562813.master.cm.cluster
++ wc -l
+ export nnodes=5
+ nnodes=5
+ export confile=/panfs/panasas01/phys/bf16951/QMD/ParallelDevelopment/Results/Jul_05/17_09/output_and_error_logs/node_info.exp-paper__simulated-data__plus-probes_23.conf
+ confile=/panfs/panasas01/phys/bf16951/QMD/ParallelDevelopment/Results/Jul_05/17_09/output_and_error_logs/node_info.exp-paper__simulated-data__plus-probes_23.conf
+ for i in '$nodes'
+ echo node44-013
+ for i in '$nodes'
+ echo node44-013
+ for i in '$nodes'
+ echo node44-013
+ for i in '$nodes'
+ echo node44-013
+ for i in '$nodes'
+ echo node44-013
+ cd /panfs/panasas01/phys/bf16951/QMD/Libraries/QML_lib
+ [[ node44-013 == \n\o\d\e* ]]
+ echo 'Launching RQ worker on remote nodes using mpirun'
+ printf 'In RUN script:  -agr ising_1d_chain -agr hubbard_square_lattice_generalised'
+ mpirun -np 5 -machinefile /panfs/panasas01/phys/bf16951/QMD/ParallelDevelopment/Results/Jul_05/17_09/output_and_error_logs/node_info.exp-paper__simulated-data__plus-probes_23.conf rq worker 23 -u redis://node44-013:6323
+ ((  0 == 0 ))
+ ALT_GROWTH=
+ sleep 5
+ cd /panfs/panasas01/phys/bf16951/QMD/ExperimentalSimulations
++ date +%H:%M:%S
+ echo 'Starting Exp.py at 06:31:10; results dir: /panfs/panasas01/phys/bf16951/QMD/ParallelDevelopment/Results/Jul_05/17_09'
+ echo '
run qmd script Doing::

cd /panfs/panasas01/phys/bf16951/QMD/ExperimentalSimulations

python3 Exp.py -mqhl=0 -rq=1 -p=2500 -e=750 -bt=750 -rt=0.5 -ra=0.98 -pgh=1.0 -pgh_exp=1.0 -pgh_incr=0 -qid=23 -rqt=200000 -g=1 -exp=0 -qhl=0 -fq=0 -pt=0 -pkl=1 -host=node44-013 -port=6323 -dir=/panfs/panasas01/phys/bf16951/QMD/ParallelDevelopment/Results/Jul_05/17_09 -log=/panfs/panasas01/phys/bf16951/QMD/ParallelDevelopment/Results/Jul_05/17_09/logs/exp-paper__simulated-data__plus-probes_23.qmd.8562813.log -cb=/panfs/panasas01/phys/bf16951/QMD/ParallelDevelopment/Results/Jul_05/17_09/cumulative.csv -cpr=1 -prtwt=0 -dst=15 -ggr=two_qubit_ising_rotation_hyperfine_transverse  -bintimes=1 -bftimesall=0 -latex=/panfs/panasas01/phys/bf16951/QMD/ParallelDevelopment/Results/Jul_05/17_09/LatexMapping.txt -nprobes=40 -prior_path=/panfs/panasas01/phys/bf16951/QMD/ParallelDevelopment/Results/Jul_05/17_09/prior.p -true_params_path=/panfs/panasas01/phys/bf16951/QMD/ParallelDevelopment/Results/Jul_05/17_09/true_params.p -plot_probes=/panfs/panasas01/phys/bf16951/QMD/ParallelDevelopment/Results/Jul_05/17_09/plot_probes.p -special_probe=random -pnoise=0.001 -true_expec_path=/panfs/panasas01/phys/bf16951/QMD/ParallelDevelopment/Results/Jul_05/17_09/true_expec_vals.p -pmin=0 -pmax=10 -pmean=0.5 -psigma=2 -resource=0 --updater_from_prior=0  
'
+ python3 Exp.py -mqhl=0 -rq=1 -p=2500 -e=750 -bt=750 -rt=0.5 -ra=0.98 -pgh=1.0 -pgh_exp=1.0 -pgh_incr=0 -qid=23 -rqt=200000 -g=1 -exp=0 -qhl=0 -fq=0 -pt=0 -pkl=1 -host=node44-013 -port=6323 -dir=/panfs/panasas01/phys/bf16951/QMD/ParallelDevelopment/Results/Jul_05/17_09 -log=/panfs/panasas01/phys/bf16951/QMD/ParallelDevelopment/Results/Jul_05/17_09/logs/exp-paper__simulated-data__plus-probes_23.qmd.8562813.log -cb=/panfs/panasas01/phys/bf16951/QMD/ParallelDevelopment/Results/Jul_05/17_09/cumulative.csv -cpr=1 -prtwt=0 -dst=15 -ggr=two_qubit_ising_rotation_hyperfine_transverse -bintimes=1 -bftimesall=0 -latex=/panfs/panasas01/phys/bf16951/QMD/ParallelDevelopment/Results/Jul_05/17_09/LatexMapping.txt -nprobes=40 -prior_path=/panfs/panasas01/phys/bf16951/QMD/ParallelDevelopment/Results/Jul_05/17_09/prior.p -true_params_path=/panfs/panasas01/phys/bf16951/QMD/ParallelDevelopment/Results/Jul_05/17_09/true_params.p -plot_probes=/panfs/panasas01/phys/bf16951/QMD/ParallelDevelopment/Results/Jul_05/17_09/plot_probes.p -special_probe=random -pnoise=0.001 -true_expec_path=/panfs/panasas01/phys/bf16951/QMD/ParallelDevelopment/Results/Jul_05/17_09/true_expec_vals.p -pmin=0 -pmax=10 -pmean=0.5 -psigma=2 -resource=0 --updater_from_prior=0
Traceback (most recent call last):
  File "/cm/shared/languages/Anaconda3-5.0.1-PHYS015202/lib/python3.6/site-packages/redis/connection.py", line 484, in connect
    sock = self._connect()
  File "/cm/shared/languages/Anaconda3-5.0.1-PHYS015202/lib/python3.6/site-packages/redis/connection.py", line 541, in _connect
    raise err
  File "/cm/shared/languages/Anaconda3-5.0.1-PHYS015202/lib/python3.6/site-packages/redis/connection.py", line 529, in _connect
    sock.connect(socket_address)
ConnectionRefusedError: [Errno 111] Connection refused

During handling of the above exception, another exception occurred:

Traceback (most recent call last):
  File "/cm/shared/languages/Anaconda3-5.0.1-PHYS015202/lib/python3.6/site-packages/redis/client.py", line 667, in execute_command
    connection.send_command(*args)
  File "/cm/shared/languages/Anaconda3-5.0.1-PHYS015202/lib/python3.6/site-packages/redis/connection.py", line 610, in send_command
    self.send_packed_command(self.pack_command(*args))
  File "/cm/shared/languages/Anaconda3-5.0.1-PHYS015202/lib/python3.6/site-packages/redis/connection.py", line 585, in send_packed_command
    self.connect()
  File "/cm/shared/languages/Anaconda3-5.0.1-PHYS015202/lib/python3.6/site-packages/redis/connection.py", line 489, in connect
    raise ConnectionError(self._error_message(e))
redis.exceptions.ConnectionError: Error 111 connecting to node44-013:6323. Connection refused.

During handling of the above exception, another exception occurred:

Traceback (most recent call last):
  File "/cm/shared/languages/Anaconda3-5.0.1-PHYS015202/lib/python3.6/site-packages/redis/connection.py", line 484, in connect
    sock = self._connect()
  File "/cm/shared/languages/Anaconda3-5.0.1-PHYS015202/lib/python3.6/site-packages/redis/connection.py", line 541, in _connect
    raise err
  File "/cm/shared/languages/Anaconda3-5.0.1-PHYS015202/lib/python3.6/site-packages/redis/connection.py", line 529, in _connect
    sock.connect(socket_address)
ConnectionRefusedError: [Errno 111] Connection refused

During handling of the above exception, another exception occurred:

Traceback (most recent call last):
  File "Exp.py", line 300, in <module>
    print_status=True),
  File "../Libraries/QML_lib/RedisSettings.py", line 71, in get_seed
    seed_db_keys = [a.decode() for a in qid_seeds.keys()]
  File "/cm/shared/languages/Anaconda3-5.0.1-PHYS015202/lib/python3.6/site-packages/redis/client.py", line 1032, in keys
    return self.execute_command('KEYS', pattern)
  File "/cm/shared/languages/Anaconda3-5.0.1-PHYS015202/lib/python3.6/site-packages/redis/client.py", line 673, in execute_command
    connection.send_command(*args)
  File "/cm/shared/languages/Anaconda3-5.0.1-PHYS015202/lib/python3.6/site-packages/redis/connection.py", line 610, in send_command
    self.send_packed_command(self.pack_command(*args))
  File "/cm/shared/languages/Anaconda3-5.0.1-PHYS015202/lib/python3.6/site-packages/redis/connection.py", line 585, in send_packed_command
    self.connect()
  File "/cm/shared/languages/Anaconda3-5.0.1-PHYS015202/lib/python3.6/site-packages/redis/connection.py", line 489, in connect
    raise ConnectionError(self._error_message(e))
redis.exceptions.ConnectionError: Error 111 connecting to node44-013:6323. Connection refused.
++ date +%H:%M:%S
+ echo 'Finished Exp.py at 06:31:16; results dir: /panfs/panasas01/phys/bf16951/QMD/ParallelDevelopment/Results/Jul_05/17_09'
+ sleep 1
+ redis-cli -p 6323 flushall
Could not connect to Redis at 127.0.0.1:6323: Connection refused
+ redis-cli -p 6323 shutdown
Could not connect to Redis at 127.0.0.1:6323: Connection refused
+ echo 8562813
++ date +%H:%M:%S
+ echo 'QMD 23 Finished; end of script at Time: 06:31:17'
